2025-03-18 16:25:16,061 [INFO] USER:konga_mamatha handlers.py:106:syndicate LOG: Configuration used: C:Userskonga_mamathaaws_taskstask03.syndicate-config-dev
2025-03-18 16:25:16,062 [ERROR] USER:konga_mamatha decorators.py:136:wrapper LOG: sdct.conf does not exist inside C:Userskonga_mamathaaws_taskstask03.syndicate-config-dev folder
2025-03-18 16:25:16,084 [ERROR] USER:konga_mamatha decorators.py:137:wrapper LOG: Traceback (most recent call last):
  File "C:\Users\konga_mamatha\AppData\Local\Programs\Python\Python313\Lib\site-packages\syndicate\core\decorators.py", line 134, in wrapper
    return_code = func(*args, **kwargs)
  File "C:\Users\konga_mamatha\AppData\Local\Programs\Python\Python313\Lib\site-packages\syndicate\core\handlers.py", line 107, in syndicate
    initialize_connection()
    ~~~~~~~~~~~~~~~~~~~~~^^
  File "C:\Users\konga_mamatha\AppData\Local\Programs\Python\Python313\Lib\site-packages\syndicate\core\__init__.py", line 106, in initialize_connection
    CONFIG = ConfigHolder(CONF_PATH)
  File "C:\Users\konga_mamatha\AppData\Local\Programs\Python\Python313\Lib\site-packages\syndicate\core\conf\processor.py", line 63, in __init__
    self._init_conf_config(dir_path=dir_path)
    ~~~~~~~~~~~~~~~~~~~~~~^^^^^^^^^^^^^^^^^^^
  File "C:\Users\konga_mamatha\AppData\Local\Programs\Python\Python313\Lib\site-packages\syndicate\core\conf\processor.py", line 92, in _init_conf_config
    raise AssertionError(
        'sdct.conf does not exist inside %s folder' % dir_path)
AssertionError: sdct.conf does not exist inside C:Userskonga_mamathaaws_taskstask03.syndicate-config-dev folder
Traceback (most recent call last):
  File "C:\Users\konga_mamatha\AppData\Local\Programs\Python\Python313\Lib\site-packages\syndicate\core\decorators.py", line 134, in wrapper
    return_code = func(*args, **kwargs)
  File "C:\Users\konga_mamatha\AppData\Local\Programs\Python\Python313\Lib\site-packages\syndicate\core\handlers.py", line 107, in syndicate
    initialize_connection()
    ~~~~~~~~~~~~~~~~~~~~~^^
  File "C:\Users\konga_mamatha\AppData\Local\Programs\Python\Python313\Lib\site-packages\syndicate\core\__init__.py", line 106, in initialize_connection
    CONFIG = ConfigHolder(CONF_PATH)
  File "C:\Users\konga_mamatha\AppData\Local\Programs\Python\Python313\Lib\site-packages\syndicate\core\conf\processor.py", line 63, in __init__
    self._init_conf_config(dir_path=dir_path)
    ~~~~~~~~~~~~~~~~~~~~~~^^^^^^^^^^^^^^^^^^^
  File "C:\Users\konga_mamatha\AppData\Local\Programs\Python\Python313\Lib\site-packages\syndicate\core\conf\processor.py", line 92, in _init_conf_config
    raise AssertionError(
        'sdct.conf does not exist inside %s folder' % dir_path)
AssertionError: sdct.conf does not exist inside C:Userskonga_mamathaaws_taskstask03.syndicate-config-dev folder
2025-03-18 16:30:09,240 [INFO] USER:konga_mamatha handlers.py:106:syndicate LOG: Configuration used: C:Userskonga_mamathaaws_taskstask03.syndicate-config-dev
2025-03-18 16:30:09,242 [ERROR] USER:konga_mamatha decorators.py:136:wrapper LOG: sdct.conf does not exist inside C:Userskonga_mamathaaws_taskstask03.syndicate-config-dev folder
2025-03-18 16:30:09,246 [ERROR] USER:konga_mamatha decorators.py:137:wrapper LOG: Traceback (most recent call last):
  File "C:\Users\konga_mamatha\AppData\Local\Programs\Python\Python313\Lib\site-packages\syndicate\core\decorators.py", line 134, in wrapper
    return_code = func(*args, **kwargs)
  File "C:\Users\konga_mamatha\AppData\Local\Programs\Python\Python313\Lib\site-packages\syndicate\core\handlers.py", line 107, in syndicate
    initialize_connection()
    ~~~~~~~~~~~~~~~~~~~~~^^
  File "C:\Users\konga_mamatha\AppData\Local\Programs\Python\Python313\Lib\site-packages\syndicate\core\__init__.py", line 106, in initialize_connection
    CONFIG = ConfigHolder(CONF_PATH)
  File "C:\Users\konga_mamatha\AppData\Local\Programs\Python\Python313\Lib\site-packages\syndicate\core\conf\processor.py", line 63, in __init__
    self._init_conf_config(dir_path=dir_path)
    ~~~~~~~~~~~~~~~~~~~~~~^^^^^^^^^^^^^^^^^^^
  File "C:\Users\konga_mamatha\AppData\Local\Programs\Python\Python313\Lib\site-packages\syndicate\core\conf\processor.py", line 92, in _init_conf_config
    raise AssertionError(
        'sdct.conf does not exist inside %s folder' % dir_path)
AssertionError: sdct.conf does not exist inside C:Userskonga_mamathaaws_taskstask03.syndicate-config-dev folder
Traceback (most recent call last):
  File "C:\Users\konga_mamatha\AppData\Local\Programs\Python\Python313\Lib\site-packages\syndicate\core\decorators.py", line 134, in wrapper
    return_code = func(*args, **kwargs)
  File "C:\Users\konga_mamatha\AppData\Local\Programs\Python\Python313\Lib\site-packages\syndicate\core\handlers.py", line 107, in syndicate
    initialize_connection()
    ~~~~~~~~~~~~~~~~~~~~~^^
  File "C:\Users\konga_mamatha\AppData\Local\Programs\Python\Python313\Lib\site-packages\syndicate\core\__init__.py", line 106, in initialize_connection
    CONFIG = ConfigHolder(CONF_PATH)
  File "C:\Users\konga_mamatha\AppData\Local\Programs\Python\Python313\Lib\site-packages\syndicate\core\conf\processor.py", line 63, in __init__
    self._init_conf_config(dir_path=dir_path)
    ~~~~~~~~~~~~~~~~~~~~~~^^^^^^^^^^^^^^^^^^^
  File "C:\Users\konga_mamatha\AppData\Local\Programs\Python\Python313\Lib\site-packages\syndicate\core\conf\processor.py", line 92, in _init_conf_config
    raise AssertionError(
        'sdct.conf does not exist inside %s folder' % dir_path)
AssertionError: sdct.conf does not exist inside C:Userskonga_mamathaaws_taskstask03.syndicate-config-dev folder
